<?xml version="1.0" ?>

<robot name="mrm" xmlns:xacro="http://www.ros.org/wiki/xacro">
    <link name="base_link">
        <visual>
            <origin rpy="0 0 0" xyz="0 0 0"/>
            <geometry>
                <box size="1.5 1 1"/>
            </geometry>
        </visual>
    </link>

    <joint name="base_link__link01" type="revolute">
        <axis xyz="0 0 1"/>
        <limit effort="1000.0" lower="-3.14" upper="3.14" velocity="0.5"/>
        <origin rpy="0 0 0" xyz="0 0 0.5"/>
        <parent link="base_link"/>
        <child link="link_01"/>
    </joint>

    <link name="link_01">
        <visual>
            <origin rpy="0 0 0" xyz="0 0 0"/>
            <geometry>
                <sphere radius="0.4"/>
            </geometry>
        </visual>
    </link>

    <joint name="link_01__link02" type="revolute">
        <axis xyz="0 1 0"/>
        <limit effort="1000.0" lower="-1.57" upper="1.57" velocity="0.5"/>
        <origin rpy="0 0 0" xyz="0 0 0.0"/>
        <parent link="link_01"/>
        <child link="link_02"/>
    </joint>

    <link name="link_02">
        <visual>
            <origin rpy="0 0 0" xyz="0 0 0.9"/>
            <geometry>
                <box size="0.5 0.1 1"/>
            </geometry>
        </visual>
    </link>

    <joint name="link_02__link03" type="revolute">
        <axis xyz="0 1 0"/>
        <limit effort="1000.0" lower="-1.57" upper="1.57" velocity="0.5"/>
        <origin rpy="0 0 0" xyz="0 0 1.4"/>
        <parent link="link_02"/>
        <child link="link_03"/>
    </joint>

    <link name="link_03">
        <visual>
            <origin rpy="0 0 0" xyz="0 0 0.5"/>
            <geometry>
                <box size="0.5 0.1 1"/>
            </geometry>
        </visual>
    </link>
</robot>
